<?xml version="1.0" ?>
<!-- =================================================================================== -->
<!-- |    This document was autogenerated by xacro from /home/ask/pollibot_ws/src/pollibot_arm_description/urdf/pollibot_arm.urdf.xacro | -->
<!-- |    EDITING THIS FILE BY HAND IS NOT RECOMMENDED                                 | -->
<!-- =================================================================================== -->
<!-- =================================================================================== -->
<!-- |    This document was autogenerated by xacro from m10ia.xacro                    | -->
<!-- |    EDITING THIS FILE BY HAND IS NOT RECOMMENDED                                 | -->
<!-- =================================================================================== -->
<robot name="pollibot">
  <link name="base_link">
    <visual>
      <origin rpy="0 0 0" xyz="0 0 0"/>
      <geometry>
        <mesh filename="package://pollibot_arm_description/meshes/visual/turtlebase.stl"/>
      </geometry>
      <material name="">
        <color rgba="0.2 0.4 0.8 1.0"/>
      </material>
    </visual>
    <collision>
      <origin rpy="0 0 0" xyz="0 0 0"/>
      <geometry>
        <mesh filename="package://pollibot_arm_description/meshes/collision/turtlebase.stl"/>
      </geometry>
    </collision>
  </link>
  <link name="waist">
    <visual>
      <origin rpy="1.5708 0 2.30383" xyz="0 0 0.1245"/>
      <geometry>
        <mesh filename="package://pollibot_arm_description/meshes/visual/waist.stl"/>
      </geometry>
      <material name="">
        <color rgba="0.0 0.5 0.0 1.0"/>
      </material>
    </visual>
    <collision>
      <origin rpy="1.5708 0 2.30383" xyz="0 0 0.1245"/>
      <geometry>
        <mesh filename="package://pollibot_arm_description/meshes/collision/waist.stl"/>
      </geometry>
    </collision>
  </link>
  <link name="link_1">
    <visual>
      <origin rpy="0 0 -2.00713" xyz="0 0 0"/>
      <geometry>
        <mesh filename="package://pollibot_arm_description/meshes/visual/link_1.stl"/>
      </geometry>
      <material name="">
        <color rgba="0.0 0.6 0.0 1.0"/>
      </material>
    </visual>
    <collision>
      <origin rpy="0 0 -2.00713" xyz="0 0 0"/>
      <geometry>
        <mesh filename="package://pollibot_arm_description/meshes/collision/link_1.stl"/>
      </geometry>
    </collision>
  </link>
  <link name="link_2">
    <visual>
      <origin rpy="0 0 -1.91986" xyz="0.0326 -0.0123 0"/>
      <geometry>
        <mesh filename="package://pollibot_arm_description/meshes/visual/link_2.stl"/>
      </geometry>
      <material name="">
        <color rgba="0.7 0.7 0.0 1.0"/>
      </material>
    </visual>
    <collision>
      <origin rpy="0 0 -1.91986" xyz="0.0326 -0.0123 0"/>
      <geometry>
        <mesh filename="package://pollibot_arm_description/meshes/collision/link_2.stl"/>
      </geometry>
    </collision>
  </link>
  <link name="endeffector">
    <visual>
      <origin rpy="0 0 0" xyz="0.01 0.014 0"/>
      <geometry>
        <mesh filename="package://pollibot_arm_description/meshes/visual/endeffector.stl"/>
      </geometry>
      <material name="">
        <color rgba="0.96 0.76 0.13 1.0"/>
      </material>
    </visual>
    <collision>
      <origin rpy="0 0 0" xyz="0.01 0.014 0"/>
      <geometry>
        <mesh filename="package://pollibot_arm_description/meshes/collision/endeffector.stl"/>
      </geometry>
    </collision>
  </link>
  <link name="pusher">
    <visual>
      <origin rpy="0 0 0" xyz="0 0 0"/>
      <geometry>
        <mesh filename="package://pollibot_arm_description/meshes/visual/pusher.stl"/>
      </geometry>
      <material name="">
        <color rgba="0.2 0.4 0.8 1.0"/>
      </material>
    </visual>
    <collision>
      <origin rpy="0 0 0" xyz="0 0 0"/>
      <geometry>
        <mesh filename="package://pollibot_arm_description/meshes/collision/pusher.stl"/>
      </geometry>
    </collision>
  </link>
  <joint name="joint_1" type="revolute">
    <origin rpy="0 0 0" xyz="0.021 -0.0313 0.0335"/>
    <parent link="base_link"/>
    <child link="waist"/>
    <axis xyz="0 0 1"/>
    <limit effort="0" lower="0.0" upper="4.71239" velocity="3.67"/>
  </joint>
  <joint name="joint_2" type="revolute">
    <origin rpy="-1.570796 2.9147 0.733038" xyz="-0.0085 -0.011 0.165"/>
    <parent link="waist"/>
    <child link="link_1"/>
    <axis xyz="0 0 1"/>
    <limit effort="0" lower="0.0" upper="4.71239" velocity="3.32"/>
  </joint>
  <joint name="joint_3" type="revolute">
    <origin rpy="0 3.141592 -2.00713" xyz="0.12688309 -0.05916655 -0.005"/>
    <parent link="link_1"/>
    <child link="link_2"/>
    <axis xyz="0 0 1"/>
    <limit effort="0" lower="0" upper="4.71239" velocity="3.67"/>
  </joint>
  <joint name="joint_4" type="revolute">
    <origin rpy="0 3.141592 0" xyz="0.11276 -0.041042 0.006"/>
    <parent link="link_2"/>
    <child link="endeffector"/>
    <axis xyz="0 0 1"/>
    <limit effort="0" lower="0" upper="4.71239" velocity="6.98"/>
  </joint>
  <joint name="joint_5" type="prismatic">
    <origin rpy="3.141592 0 1.570796" xyz="0.0041 0.02 0.0332"/>
    <parent link="endeffector"/>
    <child link="pusher"/>
    <axis xyz="1 0 0"/>
    <limit effort="0" lower="0" upper="0.087" velocity="6.98"/>
  </joint>  
</robot>
